<?xml version="1.0" ?>
<!-- =================================================================================== -->
<!-- |    This document was autogenerated by xacro from /mnt/d/ros/src/robot_description/src/description/ballbot2.urdf.xacro | -->
<!-- |    EDITING THIS FILE BY HAND IS NOT RECOMMENDED                                 | -->
<!-- =================================================================================== -->
<robot name="ballbot">
  <!-- Robot Base -->
  <link name="chassis">
    <visual>
      <geometry>
        <cylinder length="0.4" radius="0.16"/>
      </geometry>
      <material name="Cyan">
        <color rgba="0 1.0 1.0 1.0"/>
      </material>
    </visual>
    <collision>
      <geometry>
        <cylinder length="0.4" radius="0.16"/>
      </geometry>
    </collision>
  </link>
  <!-- Robot Footprint -->
  <link name="base_footprint">
    <inertial>
      <origin rpy="1.5707963267948966 0 0" xyz="0 0 0"/>
      <mass value="4"/>
      <inertia ixx="0.07893333333333333" ixy="0" ixz="0" iyy="0.07893333333333333" iyz="0" izz="0.0512"/>
    </inertial>
  </link>
  <joint name="base_joint" type="fixed">
    <parent link="chassis"/>
    <child link="base_footprint"/>
    <origin rpy="0 0 0" xyz="0.0 0.0 -0.4"/>
  </joint>
  <!-- Ball Wheel -->
  <link name="ball_wheel">
    <visual>
      <geometry>
        <sphere radius="0.2"/>
      </geometry>
      <material name="Gray">
        <color rgba="0.5 0.5 0.5 1.0"/>
      </material>
    </visual>
    <collision>
      <origin rpy="0 0 0" xyz="0 0 0"/>
      <geometry>
        <sphere radius="0.2"/>
      </geometry>
    </collision>
    <inertial>
      <mass value="2"/>
      <inertia ixx="0.03200000000000001" ixy="0.0" ixz="0.0" iyy="0.03200000000000001" iyz="0.0" izz="0.03200000000000001"/>
    </inertial>
  </link>
  <joint name="ball_wheel_joint" type="continuous">
    <parent link="chassis"/>
    <child link="ball_wheel"/>
    <origin rpy="0 0 0" xyz="0.0 0.0 -0.2"/>
  </joint>
  <link name="head">
    <visual>
      <geometry>
        <sphere radius="0.16"/>
      </geometry>
      <material name="Orange">
        <color rgba="1.0 0.57 0.15 1.0"/>
      </material>
    </visual>
    <collision>
      <geometry>
        <sphere radius="0.16"/>
      </geometry>
    </collision>
    <inertial>
      <mass value="1.5"/>
      <inertia ixx="0.015360000000000004" ixy="0.0" ixz="0.0" iyy="0.015360000000000004" iyz="0.0" izz="0.015360000000000004"/>
    </inertial>
  </link>
  <joint name="head_joint" type="fixed">
    <parent link="chassis"/>
    <child link="head"/>
    <origin rpy="0 0 0" xyz="0.0 0.0 0.2"/>
  </joint>
</robot>
