<?xml version="1.0" ?>
<sdf version='1.11'>
  <model name='robot'>
    <link name='chassis'>
      <inertial>
        <pose>0 0 -0.044999999999999998 0 0 0</pose>
        <mass>1</mass>
        <inertia>
          <ixx>0.0009637500000000002</ixx>
          <ixy>1.7060354005542469e-19</ixy>
          <ixz>-3.0593910047299102e-19</ixz>
          <iyy>0.0015659999999999999</iyy>
          <iyz>8.6665493702058186e-35</iyz>
          <izz>0.00204375</izz>
        </inertia>
      </inertial>
      <collision name='chassis_collision'>
        <pose>0 0 0 0 0 0</pose>
        <geometry>
          <box>
            <size>0.126 0.092999999999999999 0.053999999999999999</size>
          </box>
        </geometry>
      </collision>
      <visual name='chassis_visual'>
        <pose>0 0 0 0 0 0</pose>
        <geometry>
          <box>
            <size>0.126 0.092999999999999999 0.053999999999999999</size>
          </box>
        </geometry>
        <material>
          <diffuse>0 1 1 1</diffuse>
          <ambient>0 1 1 1</ambient>
        </material>
      </visual>
    </link>

    <joint name='caster_joint' type='ball'>
      <pose relative_to='chassis'>0.042000000000000003 0 -0.027 0 0 0</pose>
      <parent>chassis</parent>
      <child>caster</child>
    </joint>

    <link name='caster'>
      <pose relative_to='caster_joint'>0 0 0 0 0 0</pose>
      <inertial>
        <pose>0 0 0 0 0 0</pose>
        <mass>0.10000000000000001</mass>
        <inertia>
          <ixx>1.296e-05</ixx>
          <ixy>0</ixy>
          <ixz>0</ixz>
          <iyy>1.296e-05</iyy>
          <iyz>0</iyz>
          <izz>1.296e-05</izz>
        </inertia>
      </inertial>
      <collision name='caster_collision'>
        <pose>0 0 0 0 0 0</pose>
        <geometry>
          <sphere>
            <radius>0.017999999999999999</radius>
          </sphere>
        </geometry>
      </collision>
      <visual name='caster_visual'>
        <pose>0 0 0 0 0 0</pose>
        <geometry>
          <sphere>
            <radius>0.017999999999999999</radius>
          </sphere>
        </geometry>
        <material>
          <diffuse>0.625 0.625 0.625 1</diffuse>
          <ambient>0.625 0.625 0.625 1</ambient>
        </material>
      </visual>
    </link>

    <joint name='left_wheel_joint' type='revolute'>
      <pose relative_to='chassis'>-0.035999999999999997 0.053999999999999999 -0.014999999999999999 0 0 0</pose>
      <parent>chassis</parent>
      <child>left_wheel</child>
      <axis>
        <xyz>0 1 0</xyz>
        <limit>
          <lower>-inf</lower>
          <upper>inf</upper>
        </limit>
        <dynamics>
          <spring_reference>0</spring_reference>
          <spring_stiffness>0</spring_stiffness>
        </dynamics>
      </axis>
    </joint>

    <link name='left_wheel'>
      <pose relative_to='left_wheel_joint'>0 0 0 0 0 0</pose>
      <inertial>
        <pose>0 0 0 1.5707963267948959 0 0</pose>
        <mass>0.10000000000000001</mass>
        <inertia>
          <ixx>2.37e-05</ixx>
          <ixy>0</ixy>
          <ixz>0</ixz>
          <iyy>2.37e-05</iyy>
          <iyz>0</iyz>
          <izz>4.5000000000000003e-05</izz>
        </inertia>
      </inertial>
      <collision name='left_wheel_collision'>
        <pose>0 0 0 1.5707963267948959 0 0</pose>
        <geometry>
          <cylinder>
            <length>0.012</length>
            <radius>0.029999999999999999</radius>
          </cylinder>
        </geometry>
      </collision>
      <visual name='left_wheel_visual'>
        <pose>0 0 0 1.5707963267948959 0 0</pose>
        <geometry>
          <cylinder>
            <length>0.012</length>
            <radius>0.029999999999999999</radius>
          </cylinder>
        </geometry>
        <material>
          <diffuse>0.625 0.625 0.625 1</diffuse>
          <ambient>0.625 0.625 0.625 1</ambient>
        </material>
      </visual>
    </link>

    <joint name='right_wheel_joint' type='revolute'>
      <pose relative_to='chassis'>-0.035999999999999997 -0.053999999999999999 -0.014999999999999999 0 0 0</pose>
      <parent>chassis</parent>
      <child>right_wheel</child>
      <axis>
        <xyz>0 1 0</xyz>
        <limit>
          <lower>-inf</lower>
          <upper>inf</upper>
        </limit>
        <dynamics>
          <spring_reference>0</spring_reference>
          <spring_stiffness>0</spring_stiffness>
        </dynamics>
      </axis>
    </joint>

    <link name='right_wheel'>
      <pose relative_to='right_wheel_joint'>0 0 0 0 0 0</pose>
      <inertial>
        <pose>0 0 0 1.5707963267948959 0 0</pose>
        <mass>0.10000000000000001</mass>
        <inertia>
          <ixx>2.37e-05</ixx>
          <ixy>0</ixy>
          <ixz>0</ixz>
          <iyy>2.37e-05</iyy>
          <iyz>0</iyz>
          <izz>4.5000000000000003e-05</izz>
        </inertia>
      </inertial>
      <collision name='right_wheel_collision'>
        <pose>0 0 0 1.5707963267948959 0 0</pose>
        <geometry>
          <cylinder>
            <length>0.012</length>
            <radius>0.029999999999999999</radius>
          </cylinder>
        </geometry>
      </collision>
      <visual name='right_wheel_visual'>
        <pose>0 0 0 1.5707963267948959 0 0</pose>
        <geometry>
          <cylinder>
            <length>0.012</length>
            <radius>0.029999999999999999</radius>
          </cylinder>
        </geometry>
        <material>
          <diffuse>0.625 0.625 0.625 1</diffuse>
          <ambient>0.625 0.625 0.625 1</ambient>
        </material>
      </visual>
    </link>

    <frame name='base_joint' attached_to='chassis'>
      <pose>0 0 -0.044999999999999998 0 0 0</pose>
    </frame>

    <frame name='base_footprint' attached_to='base_joint'>
      <pose>0 0 0 0 0 0</pose>
    </frame>

    <plugin
        filename="ignition-gazebo-diff-drive-system"
        name="ignition::gazebo::systems::DiffDrive">
        <left_joint>left_wheel_joint</left_joint>
        <right_joint>right_wheel_joint</right_joint>
        <wheel_separation>0.093</wheel_separation>
        <wheel_radius>0.03</wheel_radius>
        <odom_publish_frequency>1</odom_publish_frequency>
        <max_linear_acceleration>1</max_linear_acceleration>
        <min_linear_acceleration>-1</min_linear_acceleration>
        <max_angular_acceleration>2</max_angular_acceleration>
        <min_angular_acceleration>-2</min_angular_acceleration>
        <max_linear_velocity>0.5</max_linear_velocity>
        <min_linear_velocity>-0.5</min_linear_velocity>
        <max_angular_velocity>1</max_angular_velocity>
        <min_angular_velocity>-1</min_angular_velocity>
      </plugin>

  </model>
</sdf>
