<?xml version="1.0" ?>
<!-- =================================================================================== -->
<!-- |    This document was autogenerated by xacro from robot.urdf.xacro               | -->
<!-- |    EDITING THIS FILE BY HAND IS NOT RECOMMENDED                                 | -->
<!-- =================================================================================== -->
<robot name="robot">
  <!-- Robot Base -->
  <link name="chassis">
    <visual>
      <geometry>
        <box size="0.126 0.093 0.054"/>
      </geometry>
      <material name="Cyan">
        <color rgba="0 1.0 1.0 1.0"/>
      </material>
    </visual>
    <collision>
      <geometry>
        <box size="0.126 0.093 0.054"/>
      </geometry>
    </collision>
  </link>
  <!-- Robot Footprint -->
  <link name="base_footprint">
    <inertial>
      <origin rpy="1.5707963267948966 0 1.5707963267948966" xyz="0 0 0"/>
      <mass value="1"/>
      <inertia ixx="0.001566" ixy="0.0" ixz="0.0" iyy="0.00204375" iyz="0.0" izz="0.00096375"/>
    </inertial>
  </link>
  <joint name="base_joint" type="fixed">
    <parent link="chassis"/>
    <child link="base_footprint"/>
    <origin rpy="0 0 0" xyz="0.0 0.0 -0.045"/>
  </joint>
  <link name="left_wheel">
    <visual>
      <origin rpy="1.5707963267948966 0 0" xyz="0 0 0"/>
      <geometry>
        <cylinder length="0.012" radius="0.03"/>
      </geometry>
      <material name="Gray">
        <color rgba="0.5 0.5 0.5 1.0"/>
      </material>
    </visual>
    <collision>
      <origin rpy="1.5707963267948966 0 0" xyz="0 0 0"/>
      <geometry>
        <cylinder length="0.012" radius="0.03"/>
      </geometry>
    </collision>
    <inertial>
      <origin rpy="1.5707963267948966 0 0" xyz="0 0 0"/>
      <mass value="0.1"/>
      <inertia ixx="2.3699999999999997e-05" ixy="0" ixz="0" iyy="2.3699999999999997e-05" iyz="0" izz="4.5e-05"/>
    </inertial>
  </link>
  <joint name="left_wheel_joint" type="continuous">
    <parent link="chassis"/>
    <child link="left_wheel"/>
    <origin rpy="0 0 0" xyz="-0.036 0.054 -0.015"/>
    <axis xyz="0 1 0"/>
  </joint>
  <link name="right_wheel">
    <visual>
      <origin rpy="1.5707963267948966 0 0" xyz="0 0 0"/>
      <geometry>
        <cylinder length="0.012" radius="0.03"/>
      </geometry>
      <material name="Gray">
        <color rgba="0.5 0.5 0.5 1.0"/>
      </material>
    </visual>
    <collision>
      <origin rpy="1.5707963267948966 0 0" xyz="0 0 0"/>
      <geometry>
        <cylinder length="0.012" radius="0.03"/>
      </geometry>
    </collision>
    <inertial>
      <origin rpy="1.5707963267948966 0 0" xyz="0 0 0"/>
      <mass value="0.1"/>
      <inertia ixx="2.3699999999999997e-05" ixy="0" ixz="0" iyy="2.3699999999999997e-05" iyz="0" izz="4.5e-05"/>
    </inertial>
  </link>
  <joint name="right_wheel_joint" type="continuous">
    <parent link="chassis"/>
    <child link="right_wheel"/>
    <origin rpy="0 0 0" xyz="-0.036 -0.054 -0.015"/>
    <axis xyz="0 1 0"/>
  </joint>
  <!-- Caster Wheel -->
  <link name="front_caster">
    <visual>
      <geometry>
        <sphere radius="0.018"/>
      </geometry>
      <material name="Cyan">
        <color rgba="0 1.0 1.0 1.0"/>
      </material>
    </visual>
    <collision>
      <origin rpy="0 0 0" xyz="0 0 0"/>
      <geometry>
        <sphere radius="0.018"/>
      </geometry>
    </collision>
    <inertial>
      <mass value="0.1"/>
      <inertia ixx="1.2960000000000001e-05" ixy="0.0" ixz="0.0" iyy="1.2960000000000001e-05" iyz="0.0" izz="1.2960000000000001e-05"/>
    </inertial>
  </link>
  <joint name="caster_joint" type="continuous">
    <parent link="chassis"/>
    <child link="front_caster"/>
    <origin rpy="0 0 0" xyz="0.042 0.0 -0.027"/>
  </joint>
</robot>
